<mujocoinclude>
    <body name="hingecab" childclass="hingecabinet">
        <geom material="M_hinge_blue" size="0.04 0.3 0.2" type="box"/>
        <geom material="M_hinge_blue" pos="0.38 0 0" size="0.02 0.3 0.2" type="box"/>
        <geom material="M_hinge_blue" pos="-0.38 0 0" size="0.02 0.3 0.2" type="box"/>
        <geom material="M_hinge_blue" pos="-0.2 0 0.18" size="0.16 0.3 0.02" type="box"/>
        <geom material="M_hinge_blue" pos="-0.2 0 -0.18" size="0.16 0.3 0.02" type="box"/>
        <geom material="M_hinge_blue" pos="0.2 0 -0.18" size="0.16 0.3 0.02" type="box"/>
        <geom material="M_hinge_blue" pos="0.2 0 0.18" size="0.16 0.3 0.02" type="box"/>
        <geom material="M_hinge_blue" pos="-0.2 0.28 0" size="0.16 0.02 0.16" type="box"/>
        <geom material="M_hinge_blue" pos="0.2 0.28 0" size="0.16 0.02 0.16" type="box"/>
        
        <site type="sphere" name="hinge_left_inner_site" pos="-0.2 -0.25 -0.12" size=".02" group="3" rgba="1 0 0 1"/>
        <site type="sphere" name="hinge_left_inner_behind_site" pos="-0.2 0.2 -0.12" size=".02" group="3" rgba="1 1 0 1"/>

        <site type="sphere" name="hinge_right_inner_site" pos="0.2 -0.25 -0.12" size=".02" group="3" rgba="0 1 0 1"/>
        <site type="sphere" name="hinge_right_inner_behind_site" pos="0.2 0.2 -0.12" size=".02" group="3" rgba="1 1 0 1"/>

        <geom class="hinge_collision" size="0.04 0.3 0.2" type="box" mass=".3"/>
        <geom class="hinge_collision" pos="0.38 0 0" size="0.02 0.3 0.2" type="box" mass=".2"/>
        <geom class="hinge_collision" pos="-0.38 0 0" size="0.02 0.3 0.2" type="box" mass=".2"/>
        <geom class="hinge_collision" pos="-0.2 0 0.18" size="0.16 0.3 0.02" type="box" mass=".2"/>
        <geom class="hinge_collision" pos="-0.2 0 -0.18" size="0.16 0.3 0.02" type="box" mass=".2"/>
        <geom class="hinge_collision" pos="0.2 0 -0.18" size="0.16 0.3 0.02" type="box" mass=".2"/>
        <geom class="hinge_collision" pos="0.2 0 0.18" size="0.16 0.3 0.02" type="box" mass=".2"/>
        <geom class="hinge_collision" pos="-0.2 0.28 0" size="0.16 0.02 0.16" type="box" mass=".2"/>
        <geom class="hinge_collision" pos="0.2 0.28 0" size="0.16 0.02 0.16" type="box" mass=".2"/>
        <body name="hingeleftdoor" pos="-0.38 -0.32 0">
            <joint axis="0 0 1" name="leftdoorhinge_joint" range="-2.094 0"/>
            <geom material="M_hinge_metal" pos="0.302 -0.128 0" size="0.022 0.16" type="cylinder"/>
            <geom material="M_hinge_metal" pos="0.302 -0.061 0.114" euler="1.57 0 0" size="0.019 0.053 0.02" type="cylinder"/>
            <geom material="M_hinge_metal" pos="0.302 -0.061 -0.114" euler="1.57 0 0" size="0.019 0.053 0.02" type="cylinder"/>
            <geom material="M_hinge_blue" pos="0.184 -.015 0" size="0.193 0.03 0.2" type="box"/>

            <geom class="hinge_collision" pos="0.184 -.015 0" size="0.193 0.03 0.2" type="box" mass=".2"/>
            <geom class="hinge_collision" pos="0.302 -0.128 0" size="0.022 0.16" type="cylinder" mass=".1"/>
            <geom class="hinge_collision" pos="0.302 -0.061 0.114" euler="1.57 0 0" size="0.019 0.053 0.02" type="cylinder" mass=".02"/>
            <geom class="hinge_collision" pos="0.302 -0.061 -0.114" euler="1.57 0 0" size="0.019 0.053 0.02" type="cylinder" mass=".02"/>
            <site type="sphere" name="hinge_left_door_site" pos="0.302 -0.128 0" size=".03" group="3" rgba="1 0 0 1"/>
            <site type="sphere" name="hinge_left_door_behind_site" pos="0.302 -0.028 0" size=".03" group="3" rgba="1 1 0 1"/>
        </body>
        <body name="hingerightdoor" pos="0.38 -0.32 0">
            <joint axis="0 0 1" name="rightdoorhinge_joint" range="0 2.094"/>
            <geom material="M_hinge_blue" pos="-0.185 -.015 0" size="0.193 0.03 0.2" type="box"/>
            <geom material="M_hinge_metal" pos="-0.302 -0.128 0" size="0.022 0.16" type="cylinder"/>
            <geom material="M_hinge_metal" pos="-0.302 -0.061 -0.114" euler="1.57 0 0" size="0.019 0.053 0.02" type="cylinder"/>
            <geom material="M_hinge_metal" pos="-0.302 -0.061 0.114" euler="1.57 0 0" size="0.019 0.053 0.02" type="cylinder"/>

            <geom class="hinge_collision" pos="-0.302 -0.128 0" size="0.022 0.16" type="cylinder" mass=".1"/>
            <geom class="hinge_collision" pos="-0.302 -0.061 -0.114" euler="1.57 0 0" size="0.019 0.053 0.02" type="cylinder" mass=".02"/>
            <geom class="hinge_collision" pos="-0.302 -0.061 0.114" euler="1.57 0 0" size="0.019 0.053 0.02" type="cylinder" mass=".02"/>
            <geom class="hinge_collision" pos="-0.185 -.015 0" size="0.193 0.03 0.2" type="box" mass=".2"/>
            <site type="sphere" name="hinge_right_door_site" pos="-0.302 -0.128 0" size=".03" group="3" rgba="0 1 0 1"/>
            <site type="sphere" name="hinge_right_door_behind_site" pos="-0.302 -0.028 0" size=".03" group="3" rgba="1 1 0 1"/>
        </body>
    </body>
</mujocoinclude>
