<mujocoinclude>
    <body name="microroot" childclass="microwave">
        <geom mesh="micro"/>
        <geom material="micro_metal" mesh="microbutton"/>
        <geom material="micro_metal" mesh="microfeet"/>
        <site name="micro_behind_site" type="box" pos="0.236 0.22 0.374" size=".01 .01 .01" group="3" rgba="1 1 0 1"/>
        <site name="micro_front_site" type="box" pos="0.236 -0.22 0.374" size=".01 .01 .01" group="3" rgba="1 0 0 1"/>
        <site name="micro_inner_site" type="sphere" pos="-0.08 -0.05 0.14" size=".01" group="3" rgba="1 1 0 1"/>
        <site name="micro_inner_behind_site" type="sphere" pos="-0.08 0.0 0.14" size=".01" group="3" rgba="1 0 0 1"/>
        
        <geom class="micro_collision" pos="-0.316 0.023 0.187" size="0.029 0.199 0.187" type="box" mass=".5"/>
        <geom class="micro_collision" pos="0.236 0.023 0.187" size="0.109 0.199 0.187" type="box" mass=".5"/>
        <geom class="micro_collision" pos="-0.081 0.191 0.187" size="0.207 0.03 0.187" type="box" mass=".5"/>
        <geom class="micro_collision" pos="-0.08 -0.007 0.355" size="0.207 0.169 0.019" type="box" mass=".5"/>
        <geom class="micro_collision" pos="-0.08 -0.008 0.024" size="0.207 0.168 0.024" type="box" mass=".5"/>
        <geom class="micro_collision" pos="0.26 -0.197 0.187" size="0.085 0.024 0.187" type="box" mass=".5"/>
        <body name="microdoorroot" pos="-0.345 -0.176 0.192">
            <joint axis="0 0 1" type="hinge" limited="true" name="microdoorroot_joint" range="-2.094 0"/>
            <geom mesh="microdoor" pos="0.345 0.176 -0.192"/>
            <geom material="micro_window" mesh="microwindow" pos="0.345 0.176 -0.192"/>
            <geom material="micro_metal" pos="0.475 -0.108 0" size="0.02 0.13" type="capsule"/>
            <geom material="micro_metal" euler="1.57 0 0" pos="0.475 -0.075 .13" size="0.02 0.03" type="capsule"/>
            <geom material="micro_metal" euler="1.57 0 0" pos="0.475 -0.075 -.13" size="0.02 0.03" type="capsule"/>

            <geom class="micro_collision" pos="0.475 -0.108 0" size="0.02 0.13" type="capsule" mass="0.020"/>
            <geom class="micro_collision" euler="1.57 0 0" pos="0.475 -0.075 .13" size="0.02 0.03" type="capsule" mass="0.020"/>
            <geom class="micro_collision" euler="1.57 0 0" pos="0.475 -0.075 -.13" size="0.02 0.03" type="capsule" mass="0.020"/>
            <geom class="micro_collision" pos="0.259 -0.026 0" size="0.259 0.024 0.185" type="box" mass="0.20"/>
            <site type="sphere" name="microhandle_site" pos="0.475 -0.108 0" size=".01" group="3" rgba="1 1 0 1"/>
            <site type="sphere" name="microhandle_behind_site" pos="0.475 -0.05 0" size=".01" group="3" rgba="1 0 0 1"/>
            <!-- <site name="microhandle_site" type="box" pos="0.475 -0.108 0" size=".02 .02 .04" rgba="1 1 0 1"/> -->
        </body>

        <body name="micro_timer_knob" pos="0.345 0.176 0.192">
            <joint axis="0 1 0" type="hinge"  limited="true" name="micro_timer_joint" range="0 4.188" pos="-0.1 -0.402 0.06" damping="2" frictionloss="1"/>
            <geom material="micro_metal"  euler="1.57 0 0" pos="-0.1 -0.402 0.06" size="0.025 0.005" type="cylinder" />
            <geom class="micro_collision" euler="1.57 0 0" pos="-0.1 -0.402 0.06" size="0.025 0.005" type="cylinder" mass="0.01"/>
            <site type="cylinder" name="micro_timer_knob_site" euler="1.57 0 0" pos="-0.1 -0.402 0.06" size="0.025 0.005" group="3" rgba="1 1 0 1"/>
        </body>

        <!-- <body name="micro_timer_knob 1"  euler="1.57 0 0" pos="0.245 -0.216 0.258">
            <joint axis="0 0 1" type="hinge" limited="true" name="micro_timer_joint"  range="-3.14 0"/>
            <geom material="micro_metal" type="box" pos="0 0 .038" size=".01 .025 .018"/>
            <geom material="micro_metal" type="cylinder" pos="0 0 .013" size="0.025 0.008"/>
            <geom type="cylinder" pos="0 0.025 .037" size=".01 .018" rgba="1 0 0 1"/>

            <geom class="micro_collision" type="box" pos="0 0 .038" size=".01 .025 .018" mass=".01"/>
            <geom class="micro_collision" type="cylinder" pos="0 0 .013" size="0.025 0.008" mass=".01"/>
            <site type="sphere" name="micro_timer_knob_site" pos="0 0 .038" size=".01" group="3" rgba="1 1 0 1"/>
        </body> -->

        <body name="micro_temperature_knob" pos="0.345 0.176 0.192">
            <joint axis="0 1 0" type="hinge" limited="true" name="micro_temperature_joint" range="0 4.188" pos="-0.1 -0.402 -0.04" damping="2" frictionloss="1"/>
            <geom material="micro_metal"  euler="1.57 0 0" pos="-0.1 -0.402 -0.04" size="0.025 0.005" type="cylinder" />
            <geom class="micro_collision" euler="1.57 0 0" pos="-0.1 -0.402 -0.04" size="0.025 0.005" type="cylinder" mass="0.01"/>
            <site type="cylinder" name="micro_temperature_knob_site" euler="1.57 0 0" pos="-0.1 -0.402 -0.04" size="0.025 0.005" group="3" rgba="1 1 0 1"/>
        </body>
    </body>
</mujocoinclude>
